Workbook

Sheet Read me
A1: FI Tracking Companion
A2: Spreadsheet companion to the Australian FIRE / FI tracking app. Yellow cells are inputs; blue cells are formulas. All amounts are AUD.
A4: How to use it
A5: Step | B5: Action | C5: What happens
A6: 1 | B6: Update Inputs | C6: Enter your latest balances, assumed nominal returns, debts, monthly income and monthly spending. Keep PPOR marked “No” for FI unless you deliberately intend to use it.
A7: 2 | B7: Set plans | C7: On Plans, change annual debt-free retirement spending and flexible-work income for each plan. Select one plan on Inputs to drive the projection.
A8: 3 | B8: Read the result | C8: Dashboard shows the sustainable FI capital, debt payoff, accessible pre-super bridge and projected FI month. Projection shows the monthly pathway for up to 60 years.
A9: 4 | B9: Understand the model | C9: Returns are converted from nominal to real using inflation. Cash interest is displayed in Inputs but deliberately is not added again to monthly contributions because the cash asset already compounds at its total return.
A11: Formula rules matched to the app
A12: • FI lifestyle capital = MAX(0, annual retirement spending − annual flexible-work income) ÷ withdrawal rate.
A13: • Capital required = FI lifestyle capital + every current liability. Debt payoff is a one-off requirement; retirement spending is assumed debt-free.
A14: • Accessible bridge reserve uses accessible FI assets only: spending × (1 − (1 + accessible real return)^−bridge years) ÷ accessible real return. If return is 0%, it uses spending × years.
A15: • FI is reached only when total FI assets meet capital required AND accessible FI assets meet bridge reserve + debt payoff.
A16: • Monthly projection uses real returns. External monthly contribution = manual monthly income − manual spending − liability interest. A deficit remains negative; it is not clamped to zero.
A17: • This is a planning model, not financial, tax or legal advice. It excludes tax, CGT, buying/selling costs, vacancy, repayments, insurance and transaction costs unless you enter them in spending.

Sheet Inputs
A1: Inputs
A2: Yellow cells are editable. Defaults match the current FI tracking app profile and supplied planning assumptions.
A4: Profile and active projection plan
A5: Current age | B5: 50 | C5: Age today.
A6: FI / full-time work end age | B6: 55 | C6: Target age to stop full-time work.
A7: Super access age | B7: 60 | C7: Age accessible super/SMSF is assumed available.
A8: Withdrawal rate | B8: 0.035 | C8: Sustainable withdrawal rate used for lifestyle capital.
A9: Inflation rate | B9: 0.025 | C9: Used to convert nominal asset returns to real returns.
A10: Active plan for projection | B10: Full FI plan | C10: Choose a plan from the Plans sheet.
A13: Assets
A14: Asset | B14: Current balance | C14: Nominal annual total return | D14: Include in FI? | E14: Accessible before super? | F14: Type / notes | G14: Real return
A15: Cash & savings | B15: 15000 | C15: 0.0663 | D15: Yes | E15: Yes | F15: Cash | G15: =IFERROR((1+C15)/(1+$B$9)-1,0)
A16: Super | B16: 461683 | C16: 0.075 | D16: Yes | E16: No | F16: Superannuation | G16: =IFERROR((1+C16)/(1+$B$9)-1,0)
A17: ETFs | B17: 7021017 | C17: 0.2 | D17: Yes | E17: Yes | F17: Investment | G17: =IFERROR((1+C17)/(1+$B$9)-1,0)
A18: Direct shares | B18: 335753 | C18: 0.07 | D18: Yes | E18: Yes | F18: Investment | G18: =IFERROR((1+C18)/(1+$B$9)-1,0)
A19: Primary residence | B19: 2790000 | C19: 0.07 | D19: No | E19: No | F19: Primary residence | G19: =IFERROR((1+C19)/(1+$B$9)-1,0)
A20: Investment property | B20: 2410000 | C20: 0.07 | D20: Yes | E20: Yes | F20: Investment property | G20: =IFERROR((1+C20)/(1+$B$9)-1,0)
A21: SMSF | B21: 69239 | C21: 0.07 | D21: Yes | E21: No | F21: Superannuation | G21: =IFERROR((1+C21)/(1+$B$9)-1,0)
B22: 0 | C22: 0 | D22: No | E22: No | G22: =IFERROR((1+C22)/(1+$B$9)-1,0)
B23: 0 | C23: 0 | D23: No | E23: No | G23: =IFERROR((1+C23)/(1+$B$9)-1,0)
B24: 0 | C24: 0 | D24: No | E24: No | G24: =IFERROR((1+C24)/(1+$B$9)-1,0)
B25: 0 | C25: 0 | D25: No | E25: No | G25: =IFERROR((1+C25)/(1+$B$9)-1,0)
B26: 0 | C26: 0 | D26: No | E26: No | G26: =IFERROR((1+C26)/(1+$B$9)-1,0)
B27: 0 | C27: 0 | D27: No | E27: No | G27: =IFERROR((1+C27)/(1+$B$9)-1,0)
B28: 0 | C28: 0 | D28: No | E28: No | G28: =IFERROR((1+C28)/(1+$B$9)-1,0)
B29: 0 | C29: 0 | D29: No | E29: No | G29: =IFERROR((1+C29)/(1+$B$9)-1,0)
B30: 0 | C30: 0 | D30: No | E30: No | G30: =IFERROR((1+C30)/(1+$B$9)-1,0)
B31: 0 | C31: 0 | D31: No | E31: No | G31: =IFERROR((1+C31)/(1+$B$9)-1,0)
B32: 0 | C32: 0 | D32: No | E32: No | G32: =IFERROR((1+C32)/(1+$B$9)-1,0)
B33: 0 | C33: 0 | D33: No | E33: No | G33: =IFERROR((1+C33)/(1+$B$9)-1,0)
B34: 0 | C34: 0 | D34: No | E34: No | G34: =IFERROR((1+C34)/(1+$B$9)-1,0)
A37: Liabilities — all included as debt payoff capital
A38: Liability | B38: Current balance | C38: Annual interest rate | D38: Linked asset / notes | E38: Monthly interest
A39: Chatswood loan | B39: 505000 | C39: 0.0599 | D39: Primary residence | E39: =B39*C39/12
A40: Wahroonga loan | B40: 1660000 | C40: 0.0663 | D40: Investment property | E40: =B40*C40/12
A41: Family loan | B41: 24000 | C41: 0 | D41: Unlinked | E41: =B41*C41/12
A42: Line of credit | B42: 0 | C42: 0.0846 | D42: Unlinked | E42: =B42*C42/12
A43: Credit card debt | B43: 0 | C43: 0.08 | D43: Unlinked | E43: =B43*C43/12
B44: 0 | C44: 0 | E44: =B44*C44/12
B45: 0 | C45: 0 | E45: =B45*C45/12
...

Sheet Plans
A1: Plans
A2: Edit the yellow annual spending and flexible-work income assumptions. Every plan includes clearing all current debt because retirement spending is debt-free.
A4: Plan | B4: Annual debt-free retirement spending | C4: Annual flexible-work income | D4: Net annual spending | E4: FI lifestyle capital | F4: Debt payoff | G4: Capital required | H4: Years to FI age | I4: Weighted FI real return | J4: Accessible FI assets | K4: Restricted super / SMSF | L4: Accessible real return | M4: Restricted real return | N4: Bridge years | O4: Bridge reserve | P4: Accessible threshold (bridge + debt) | Q4: External monthly contribution | R4: Current FI assets | S4: Funded % | T4: Liquidity status
A5: Full FI plan | B5: 320000 | C5: 0 | D5: =MAX(0,B5-C5) | E5: =IFERROR(D5/Inputs!$B$8,0) | F5: =SUM(Inputs!$B$39:$B$53) | G5: =E5+F5 | H5: =MAX(0,Inputs!$B$6-Inputs!$B$5) | I5: =IFERROR(SUMPRODUCT((Inputs!$D$15:$D$34="Yes")*Inputs!$B$15:$B$34*Inputs!$G$15:$G$34)/SUMIF(Inputs!$D$15:$D$34,"Yes",Inputs!$B$15:$B$34),0) | J5: =SUMIFS(Inputs!$B$15:$B$34,Inputs!$D$15:$D$34,"Yes",Inputs!$E$15:$E$34,"Yes") | K5: =SUMIFS(Inputs!$B$15:$B$34,Inputs!$D$15:$D$34,"Yes",Inputs!$E$15:$E$34,"No") | L5: =IFERROR(SUMPRODUCT((Inputs!$D$15:$D$34="Yes")*(Inputs!$E$15:$E$34="Yes")*Inputs!$B$15:$B$34*Inputs!$G$15:$G$34)/J5,0) | M5: =IFERROR(SUMPRODUCT((Inputs!$D$15:$D$34="Yes")*(Inputs!$E$15:$E$34="No")*Inputs!$B$15:$B$34*Inputs!$G$15:$G$34)/K5,0) | N5: =MAX(0,Inputs!$B$7-Inputs!$B$6) | O5: =IF(N5=0,0,IF(ABS(L5)<0.000000000001,D5*N5,D5*(1-(1+L5)^-N5)/L5)) | P5: =O5+F5 | Q5: =Inputs!$B$70-Inputs!$E$70-Inputs!$E$71 | R5: =J5+K5 | S5: =IFERROR(R5/G5,0) | T5: =IF(J5>=P5,"Accessible bridge funded","Accessible bridge gap")
A6: Debt-free plan | B6: 320000 | C6: 0 | D6: =MAX(0,B6-C6) | E6: =IFERROR(D6/Inputs!$B$8,0) | F6: =SUM(Inputs!$B$39:$B$53) | G6: =E6+F6 | H6: =MAX(0,Inputs!$B$6-Inputs!$B$5) | I6: =IFERROR(SUMPRODUCT((Inputs!$D$15:$D$34="Yes")*Inputs!$B$15:$B$34*Inputs!$G$15:$G$34)/SUMIF(Inputs!$D$15:$D$34,"Yes",Inputs!$B$15:$B$34),0) | J6: =SUMIFS(Inputs!$B$15:$B$34,Inputs!$D$15:$D$34,"Yes",Inputs!$E$15:$E$34,"Yes") | K6: =SUMIFS(Inputs!$B$15:$B$34,Inputs!$D$15:$D$34,"Yes",Inputs!$E$15:$E$34,"No") | L6: =IFERROR(SUMPRODUCT((Inputs!$D$15:$D$34="Yes")*(Inputs!$E$15:$E$34="Yes")*Inputs!$B$15:$B$34*Inputs!$G$15:$G$34)/J6,0) | M6: =IFERROR(SUMPRODUCT((Inputs!$D$15:$D$34="Yes")*(Inputs!$E$15:$E$34="No")*Inputs!$B$15:$B$34*Inputs!$G$15:$G$34)/K6,0) | N6: =MAX(0,Inputs!$B$7-Inputs!$B$6) | O6: =IF(N6=0,0,IF(ABS(L6)<0.000000000001,D6*N6,D6*(1-(1+L6)^-N6)/L6)) | P6: =O6+F6 | Q6: =Inputs!$B$70-Inputs!$E$70-Inputs!$E$71 | R6: =J6+K6 | S6: =IFERROR(R6/G6,0) | T6: =IF(J6>=P6,"Accessible bridge funded","Accessible bridge gap")
A7: Flexible work plan | B7: 320000 | C7: 0 | D7: =MAX(0,B7-C7) | E7: =IFERROR(D7/Inputs!$B$8,0) | F7: =SUM(Inputs!$B$39:$B$53) | G7: =E7+F7 | H7: =MAX(0,Inputs!$B$6-Inputs!$B$5) | I7: =IFERROR(SUMPRODUCT((Inputs!$D$15:$D$34="Yes")*Inputs!$B$15:$B$34*Inputs!$G$15:$G$34)/SUMIF(Inputs!$D$15:$D$34,"Yes",Inputs!$B$15:$B$34),0) | J7: =SUMIFS(Inputs!$B$15:$B$34,Inputs!$D$15:$D$34,"Yes",Inputs!$E$15:$E$34,"Yes") | K7: =SUMIFS(Inputs!$B$15:$B$34,Inputs!$D$15:$D$34,"Yes",Inputs!$E$15:$E$34,"No") | L7: =IFERROR(SUMPRODUCT((Inputs!$D$15:$D$34="Yes")*(Inputs!$E$15:$E$34="Yes")*Inputs!$B$15:$B$34*Inputs!$G$15:$G$34)/J7,0) | M7: =IFERROR(SUMPRODUCT((Inputs!$D$15:$D$34="Yes")*(Inputs!$E$15:$E$34="No")*Inputs!$B$15:$B$34*Inputs!$G$15:$G$34)/K7,0) | N7: =MAX(0,Inputs!$B$7-Inputs!$B$6) | O7: =IF(N7=0,0,IF(ABS(L7)<0.000000000001,D7*N7,D7*(1-(1+L7)^-N7)/L7)) | P7: =O7+F7 | Q7: =Inputs!$B$70-Inputs!$E$70-Inputs!$E$71 | R7: =J7+K7 | S7: =IFERROR(R7/G7,0) | T7: =IF(J7>=P7,"Accessible bridge funded","Accessible bridge gap")

Sheet Projection
A1: Projection
A2: Monthly real-return projection for the active plan selected on Inputs. It tests both total capital and the accessible pre-super bridge.
A4: Active plan settings (formula-linked)
A5: Selected plan | B5: =Inputs!$B$10
A6: Capital required | B6: =INDEX(Plans!$G$5:$G$7,MATCH(B5,Plans!$A$5:$A$7,0))
A7: Accessible threshold | B7: =INDEX(Plans!$P$5:$P$7,MATCH(B5,Plans!$A$5:$A$7,0))
A8: Accessible real return | B8: =INDEX(Plans!$L$5:$L$7,MATCH(B5,Plans!$A$5:$A$7,0))
A9: Restricted real return | B9: =INDEX(Plans!$M$5:$M$7,MATCH(B5,Plans!$A$5:$A$7,0))
A10: External monthly contribution | B10: =INDEX(Plans!$Q$5:$Q$7,MATCH(B5,Plans!$A$5:$A$7,0))
A11: Starting accessible FI assets | B11: =INDEX(Plans!$J$5:$J$7,MATCH(B5,Plans!$A$5:$A$7,0))
A12: Starting restricted super / SMSF | B12: =INDEX(Plans!$K$5:$K$7,MATCH(B5,Plans!$A$5:$A$7,0))
A15: Month | B15: Date | C15: Age | D15: Accessible FI assets | E15: Restricted super / SMSF | F15: Total FI assets | G15: Capital required | H15: Accessible threshold | I15: FI reached? | J15: Notes
A16: 0 | B16: =EDATE(TODAY(),A16) | C16: =Inputs!$B$5+A16/12 | D16: =$B$11 | E16: =$B$12 | F16: =D16+E16 | G16: =$B$6 | H16: =$B$7 | I16: =IF(AND(F16>=G16,D16>=H16),"FI reached","") | J16: =IF(A16=720,"60-year model limit","")
A17: 1 | B17: =EDATE(TODAY(),A17) | C17: =Inputs!$B$5+A17/12 | D17: =D16*(1+$B$8)^(1/12)+$B$10 | E17: =E16*(1+$B$9)^(1/12) | F17: =D17+E17 | G17: =$B$6 | H17: =$B$7 | I17: =IF(AND(F17>=G17,D17>=H17),"FI reached","") | J17: =IF(A17=720,"60-year model limit","")
A18: 2 | B18: =EDATE(TODAY(),A18) | C18: =Inputs!$B$5+A18/12 | D18: =D17*(1+$B$8)^(1/12)+$B$10 | E18: =E17*(1+$B$9)^(1/12) | F18: =D18+E18 | G18: =$B$6 | H18: =$B$7 | I18: =IF(AND(F18>=G18,D18>=H18),"FI reached","") | J18: =IF(A18=720,"60-year model limit","")
A19: 3 | B19: =EDATE(TODAY(),A19) | C19: =Inputs!$B$5+A19/12 | D19: =D18*(1+$B$8)^(1/12)+$B$10 | E19: =E18*(1+$B$9)^(1/12) | F19: =D19+E19 | G19: =$B$6 | H19: =$B$7 | I19: =IF(AND(F19>=G19,D19>=H19),"FI reached","") | J19: =IF(A19=720,"60-year model limit","")
A20: 4 | B20: =EDATE(TODAY(),A20) | C20: =Inputs!$B$5+A20/12 | D20: =D19*(1+$B$8)^(1/12)+$B$10 | E20: =E19*(1+$B$9)^(1/12) | F20: =D20+E20 | G20: =$B$6 | H20: =$B$7 | I20: =IF(AND(F20>=G20,D20>=H20),"FI reached","") | J20: =IF(A20=720,"60-year model limit","")
A21: 5 | B21: =EDATE(TODAY(),A21) | C21: =Inputs!$B$5+A21/12 | D21: =D20*(1+$B$8)^(1/12)+$B$10 | E21: =E20*(1+$B$9)^(1/12) | F21: =D21+E21 | G21: =$B$6 | H21: =$B$7 | I21: =IF(AND(F21>=G21,D21>=H21),"FI reached","") | J21: =IF(A21=720,"60-year model limit","")
A22: 6 | B22: =EDATE(TODAY(),A22) | C22: =Inputs!$B$5+A22/12 | D22: =D21*(1+$B$8)^(1/12)+$B$10 | E22: =E21*(1+$B$9)^(1/12) | F22: =D22+E22 | G22: =$B$6 | H22: =$B$7 | I22: =IF(AND(F22>=G22,D22>=H22),"FI reached","") | J22: =IF(A22=720,"60-year model limit","")
A23: 7 | B23: =EDATE(TODAY(),A23) | C23: =Inputs!$B$5+A23/12 | D23: =D22*(1+$B$8)^(1/12)+$B$10 | E23: =E22*(1+$B$9)^(1/12) | F23: =D23+E23 | G23: =$B$6 | H23: =$B$7 | I23: =IF(AND(F23>=G23,D23>=H23),"FI reached","") | J23: =IF(A23=720,"60-year model limit","")
A24: 8 | B24: =EDATE(TODAY(),A24) | C24: =Inputs!$B$5+A24/12 | D24: =D23*(1+$B$8)^(1/12)+$B$10 | E24: =E23*(1+$B$9)^(1/12) | F24: =D24+E24 | G24: =$B$6 | H24: =$B$7 | I24: =IF(AND(F24>=G24,D24>=H24),"FI reached","") | J24: =IF(A24=720,"60-year model limit","")
A25: 9 | B25: =EDATE(TODAY(),A25) | C25: =Inputs!$B$5+A25/12 | D25: =D24*(1+$B$8)^(1/12)+$B$10 | E25: =E24*(1+$B$9)^(1/12) | F25: =D25+E25 | G25: =$B$6 | H25: =$B$7 | I25: =IF(AND(F25>=G25,D25>=H25),"FI reached","") | J25: =IF(A25=720,"60-year model limit","")
A26: 10 | B26: =EDATE(TODAY(),A26) | C26: =Inputs!$B$5+A26/12 | D26: =D25*(1+$B$8)^(1/12)+$B$10 | E26: =E25*(1+$B$9)^(1/12) | F26: =D26+E26 | G26: =$B$6 | H26: =$B$7 | I26: =IF(AND(F26>=G26,D26>=H26),"FI reached","") | J26: =IF(A26=720,"60-year model limit","")
A27: 11 | B27: =EDATE(TODAY(),A27) | C27: =Inputs!$B$5+A27/12 | D27: =D26*(1+$B$8)^(1/12)+$B$10 | E27: =E26*(1+$B$9)^(1/12) | F27: =D27+E27 | G27: =$B$6 | H27: =$B$7 | I27: =IF(AND(F27>=G27,D27>=H27),"FI reached","") | J27: =IF(A27=720,"60-year model limit","")
A28: 12 | B28: =EDATE(TODAY(),A28) | C28: =Inputs!$B$5+A28/12 | D28: =D27*(1+$B$8)^(1/12)+$B$10 | E28: =E27*(1+$B$9)^(1/12) | F28: =D28+E28 | G28: =$B$6 | H28: =$B$7 | I28: =IF(AND(F28>=G28,D28>=H28),"FI reached","") | J28: =IF(A28=720,"60-year model limit","")
... A736: 720 | B736: =EDATE(TODAY(),A736) | C736: =Inputs!$B$5+A736/12 | D736: =D735*(1+$B$8)^(1/12)+$B$10 | E736: =E735*(1+$B$9)^(1/12) | F736: =D736+E736 | G736: =$B$6 | H736: =$B$7 | I736: =IF(AND(F736>=G736,D736>=H736),"FI reached","") | J736: =IF(A736=720,"60-year model limit","")

Sheet Dashboard
A1: FI Dashboard
A2: Live formula summary. Change yellow cells on Inputs and Plans; then choose the active plan on Inputs to test its monthly projection.
A4: Selected plan summary
A5: =Inputs!$B$10
A7: Annual debt-free retirement spending | B7: =INDEX(Plans!$B$5:$B$7,MATCH(Inputs!$B$10,Plans!$A$5:$A$7,0))
A8: Annual flexible-work income | B8: =INDEX(Plans!$C$5:$C$7,MATCH(Inputs!$B$10,Plans!$A$5:$A$7,0))
A9: Net annual spending | B9: =INDEX(Plans!$D$5:$D$7,MATCH(Inputs!$B$10,Plans!$A$5:$A$7,0))
A10: FI lifestyle capital | B10: =INDEX(Plans!$E$5:$E$7,MATCH(Inputs!$B$10,Plans!$A$5:$A$7,0))
A11: Current debt payoff | B11: =INDEX(Plans!$F$5:$F$7,MATCH(Inputs!$B$10,Plans!$A$5:$A$7,0))
A12: Capital required | B12: =INDEX(Plans!$G$5:$G$7,MATCH(Inputs!$B$10,Plans!$A$5:$A$7,0))
A13: Current FI assets | B13: =INDEX(Plans!$R$5:$R$7,MATCH(Inputs!$B$10,Plans!$A$5:$A$7,0))
A14: Accessible bridge reserve | B14: =INDEX(Plans!$O$5:$O$7,MATCH(Inputs!$B$10,Plans!$A$5:$A$7,0))
A15: Accessible bridge + debt threshold | B15: =INDEX(Plans!$P$5:$P$7,MATCH(Inputs!$B$10,Plans!$A$5:$A$7,0))
A16: External monthly contribution | B16: =INDEX(Plans!$Q$5:$Q$7,MATCH(Inputs!$B$10,Plans!$A$5:$A$7,0))
A17: Projected FI month | B17: =IFERROR(EDATE(TODAY(),MATCH("FI reached",Projection!$I$16:$I$736,0)-1),"")
A18: Model status | B18: =IFERROR(IF(MATCH("FI reached",Projection!$I$16:$I$736,0)>0,"FI and bridge reached","Not reached in 60 years"),"Not reached in 60 years")
A21: Interpretation
A22: • Capital required combines sustainable lifestyle capital and all current debt. It is expressed in today’s dollars because the projections use real returns.
A23: • The bridge test is separate: accessible assets must fund spending before super access and still provide the debt payoff. Super/SMSF is not treated as available before the selected access age.
A24: • The projection uses the displayed monthly income and spending only. It does not include tax, CGT, property-sale costs, vacancy, loan principal repayments or other costs unless you enter them.
A25: • The default 20% ETF return is an optimistic input, not a forecast. Test lower assumptions and higher spending/debt costs before relying on a date.
